<?xml version="1.0"?>
<robot name="piston">
  <link name="base_link">
    <inertial>
      <mass value="1.0"/>
      <inertia ixx="1.0" ixy="0.0" ixz="0.0" iyy="1.0" iyz="0.0" izz="1.0"/>
      <origin xyz="0 0 0" rpy="0 0 0"/>
    </inertial>
    <visual>
      <geometry>
        <box size="0.5 0.5 0.5"/>
      </geometry>
      <origin xyz="0 0 0" rpy="0 0 0"/>
      <material name="green"/>
    </visual>
    <collision>
      <geometry>
        <box size="0.5 0.5 0.5"/>
      </geometry>
      <origin xyz="0 0 0" rpy="0 0 0"/>
    </collision>
  </link>

  <joint name="piston_joint" type="prismatic">
    <parent link="base_link"/>
    <child link="piston_link"/>
    <origin xyz="0 0 0" rpy="0 0 0"/>
    <axis xyz="0 0 1"/>
    <limit lower="0" upper="0.5" effort="1000" velocity="1.0"/>
  </joint>

  <link name="piston_link">
    <inertial>
      <mass value="0.5"/>
      <inertia ixx="0.5" ixy="0.0" ixz="0.0" iyy="0.5" iyz="0.0" izz="0.5"/>
      <origin xyz="0 0 0" rpy="0 0 0"/>
    </inertial>
    <visual>
      <geometry>
        <cylinder radius="0.1" length="1.0"/>
      </geometry>
      <origin xyz="0 0 0" rpy="0 0 0"/>
      <material name="blue"/>
    </visual>
    <collision>
      <geometry>
        <cylinder radius="0.1" length="1.0"/>
      </geometry>
      <origin xyz="0 0 0" rpy="0 0 0"/>
    </collision>
  </link>
</robot>
